Workbook

Sheet Tasks
A1: 601 | C1: Steel Design | D1: Design Code | E1: Design Code | H1: DESIGN | I1: STEEL | K1: DSTL | L1: =_xlfn.TEXTJOIN("/",TRUE,H1,I1,J1,K1) | N1: done | O1: done | P1: progress | S1: warning | T1: Done | V1: 기존변경필요 | X1: get, put 만 가능 (T_DSTL_D) | Z1: =IF(OR(K1="",K1="TABLE"),"", _xlfn.TEXTJOIN(", ",TRUE, IF(E1<>"",E1&K1,""), IF(F1<>"",F1&K1,""), IF(G1<>"",G1&K1,"") )) | AA1: =IF(K1="","",IF(K1="TABLE","",K1)) | AB1: =IF(ISNUMBER(SEARCH("기존변경필요",SUBSTITUTE(TRIM(V1),CHAR(10)," "))),"", IFERROR( _xlfn.XLOOKUP(AA1,'기존 end point'!B:B,'기존 end point'!B:B,,0), ""))
A2: Order | B2: Product | C2: Tab | D2: Group | E2: sub1 | F2: sub2 | G2: sub3 | H2: seg1 | I2: seg2 | J2: seg3 | K2: seg4 | L2: End Point | M2: mode | N2: Plan | O2: Dev | P2: V&V | Q2: doc | R2: Deploy | S2: Issue | T2: status | U2: charge | V2: remark | X2: 개발 비고
A3: 1 | B3: civil-nx/gen-nx | C3: View | D3: View | E3: View Point | F3: Rotate Up | H3: view | N3: done | O3: done | P3: done | Q3: done | R3: done | S3: done | T3: Done | Z3: =IF(OR(K3="",K3="TABLE"),"", _xlfn.TEXTJOIN(", ",TRUE, IF(E3<>"",E3&K3,""), IF(F3<>"",F3&K3,""), IF(G3<>"",G3&K3,"") )) | AA3: =IF(K3="","",IF(K3="TABLE","",K3)) | AB3: =IF(ISNUMBER(SEARCH("기존변경필요",SUBSTITUTE(TRIM(V3),CHAR(10)," "))),"", IFERROR( _xlfn.XLOOKUP(AA3,'기존 end point'!B:B,'기존 end point'!B:B,,0), ""))
A4: 2 | B4: civil-nx/gen-nx | C4: View | D4: View | E4: View Point | F4: Angle | H4: view | I4: angle | K4: =_xlfn.TEXTAFTER(L4,"/",-1) | L4: /view/angle | M4: Viewpoint | N4: done | O4: done | P4: done | Q4: done | R4: done | S4: done | T4: Done | Z4: =IF(OR(K4="",K4="TABLE"),"", _xlfn.TEXTJOIN(", ",TRUE, IF(E4<>"",E4&K4,""), IF(F4<>"",F4&K4,""), IF(G4<>"",G4&K4,"") )) | AA4: =IF(K4="","",IF(K4="TABLE","",K4)) | AB4: =IF(ISNUMBER(SEARCH("기존변경필요",SUBSTITUTE(TRIM(V4),CHAR(10)," "))),"", IFERROR( _xlfn.XLOOKUP(AA4,'기존 end point'!B:B,'기존 end point'!B:B,,0), ""))
A5: 3 | B5: civil-nx/gen-nx | C5: View | D5: View | E5: View Point | F5: Rotate Left | H5: view | T5: none | Z5: =IF(OR(K5="",K5="TABLE"),"", _xlfn.TEXTJOIN(", ",TRUE, IF(E5<>"",E5&K5,""), IF(F5<>"",F5&K5,""), IF(G5<>"",G5&K5,"") )) | AA5: =IF(K5="","",IF(K5="TABLE","",K5)) | AB5: =IF(ISNUMBER(SEARCH("기존변경필요",SUBSTITUTE(TRIM(V5),CHAR(10)," "))),"", IFERROR( _xlfn.XLOOKUP(AA5,'기존 end point'!B:B,'기존 end point'!B:B,,0), ""))
A6: 4 | B6: civil-nx/gen-nx | C6: View | D6: View | E6: View Point | F6: Rotate Right | H6: view | T6: none | Z6: =IF(OR(K6="",K6="TABLE"),"", _xlfn.TEXTJOIN(", ",TRUE, IF(E6<>"",E6&K6,""), IF(F6<>"",F6&K6,""), IF(G6<>"",G6&K6,"") )) | AA6: =IF(K6="","",IF(K6="TABLE","",K6)) | AB6: =IF(ISNUMBER(SEARCH("기존변경필요",SUBSTITUTE(TRIM(V6),CHAR(10)," "))),"", IFERROR( _xlfn.XLOOKUP(AA6,'기존 end point'!B:B,'기존 end point'!B:B,,0), ""))
A7: 5 | B7: civil-nx/gen-nx | C7: Project | D7: API | E7: New Project | H7: doc | I7: new | K7: =_xlfn.TEXTAFTER(L7,"/",-1) | L7: /doc/new | O7: done | P7: done | Q7: done | R7: done | S7: done | T7: none | Z7: =IF(OR(K7="",K7="TABLE"),"", _xlfn.TEXTJOIN(", ",TRUE, IF(E7<>"",E7&K7,""), IF(F7<>"",F7&K7,""), IF(G7<>"",G7&K7,"") )) | AA7: =IF(K7="","",IF(K7="TABLE","",K7)) | AB7: =IF(ISNUMBER(SEARCH("기존변경필요",SUBSTITUTE(TRIM(V7),CHAR(10)," "))),"", IFERROR( _xlfn.XLOOKUP(AA7,'기존 end point'!B:B,'기존 end point'!B:B,,0), ""))
A8: 6 | B8: civil-nx/gen-nx | C8: Project | D8: API | E8: Open Project | H8: doc | I8: open | K8: =_xlfn.TEXTAFTER(L8,"/",-1) | L8: /doc/open | N8: done | O8: done | P8: done | Q8: done | R8: done | S8: done | T8: Done | Z8: =IF(OR(K8="",K8="TABLE"),"", _xlfn.TEXTJOIN(", ",TRUE, IF(E8<>"",E8&K8,""), IF(F8<>"",F8&K8,""), IF(G8<>"",G8&K8,"") )) | AA8: =IF(K8="","",IF(K8="TABLE","",K8)) | AB8: =IF(ISNUMBER(SEARCH("기존변경필요",SUBSTITUTE(TRIM(V8),CHAR(10)," "))),"", IFERROR( _xlfn.XLOOKUP(AA8,'기존 end point'!B:B,'기존 end point'!B:B,,0), ""))
A9: 7 | B9: civil-nx/gen-nx | C9: Project | D9: API | E9: Close Project | H9: doc | I9: close | K9: =_xlfn.TEXTAFTER(L9,"/",-1) | L9: /doc/close | N9: done | O9: done | P9: done | Q9: done | R9: done | S9: done | T9: Done | Z9: =IF(OR(K9="",K9="TABLE"),"", _xlfn.TEXTJOIN(", ",TRUE, IF(E9<>"",E9&K9,""), IF(F9<>"",F9&K9,""), IF(G9<>"",G9&K9,"") )) | AA9: =IF(K9="","",IF(K9="TABLE","",K9)) | AB9: =IF(ISNUMBER(SEARCH("기존변경필요",SUBSTITUTE(TRIM(V9),CHAR(10)," "))),"", IFERROR( _xlfn.XLOOKUP(AA9,'기존 end point'!B:B,'기존 end point'!B:B,,0), ""))
C10: DOC | D10: DOC | E10: Save | H10: DOC | I10: SAVE | L10: /DOC/SAVE | V10: POST
A11: 8 | B11: civil-nx/gen-nx | C11: Project | D11: API | E11: Save As | L11: /doc/stagas | N11: done | O11: done | P11: done | Q11: done | R11: done | S11: done | T11: Done
A12: 9 | B12: civil-nx/gen-nx | C12: Project | D12: API | E12: Save Current Stage As | L12: /doc/import | N12: done | O12: done | P12: done | Q12: done | R12: done | S12: done | T12: Done
A13: 10 | B13: civil-nx/gen-nx | C13: Project | D13: API | E13: Import to Json | L13: /doc/importmxt | N13: done | O13: done | P13: done | Q13: done | R13: done | S13: done | T13: Done
A14: 11 | B14: civil-nx/gen-nx | C14: Project | D14: API | E14: Import to mct/mgt | L14: /doc/export | N14: done | O14: done | P14: done | Q14: done | R14: done | S14: done | T14: Done
A15: 12 | B15: civil-nx/gen-nx | C15: Project | D15: API | E15: Export to Json | L15: /doc/exportmxt | N15: done | O15: done | P15: done | Q15: done | R15: done | S15: done | T15: Done
A16: 13 | B16: civil-nx/gen-nx | C16: Project | D16: API | E16: Export to mct/mgt | T16: none
A17: 14 | B17: civil-nx/gen-nx | C17: Project | D17: Management | E17: Project Information | F17: - | G17: - | L17: db/pjcf | N17: done | O17: done | P17: done | Q17: done | R17: done | S17: done | T17: Done
A18: 15 | B18: civil-nx/gen-nx | C18: Project | D18: Management | E18: Preference | F18: - | G18: - | T18: none
A19: 16 | B19: civil-nx/gen-nx | C19: Project | D19: Management | E19: Project Status | F19: - | G19: - | L19: ope/projectstatus | N19: done | O19: done | P19: done | Q19: done | R19: done | S19: done | T19: Done
A20: 17 | B20: civil-nx/gen-nx | C20: Project | D20: Settings | E20: Unit System | F20: - | G20: - | L20: db/unit | N20: done | O20: done | P20: done | Q20: done | R20: done | S20: done | T20: Done
A21: 18 | B21: civil-nx/gen-nx | C21: Project | D21: Bill | E21: Bill of Material | F21: - | G21: - | T21: none
A22: 19 | B22: civil-nx/gen-nx | C22: Project | D22: API | E22: Material Color | L22: /db/co_m | N22: done | O22: done | P22: done | Q22: done | R22: done | S22: done | T22: Done
A23: 20 | B23: civil-nx/gen-nx | C23: Project | D23: API | E23: Section Color | L23: /db/co_s | N23: done | O23: done | P23: done | Q23: done | R23: done | S23: done | T23: Done
A24: 21 | B24: civil-nx/gen-nx | C24: Project | D24: API | E24: Thickness Color | L24: /db/co_t | N24: done | O24: done | P24: done | Q24: done | R24: done | S24: done | T24: Done
A25: 22 | B25: civil-nx/gen-nx | C25: Project | D25: API | E25: Floor Load Color | L25: /db/co_f | N25: done | O25: done | P25: done | Q25: done | R25: done | S25: done | T25: Done
A26: 23 | B26: civil-nx/gen-nx | C26: View | D26: View | E26: View | F26: Initial View | T26: none
A27: 24 | B27: civil-nx/gen-nx | C27: View | D27: View | E27: View | F27: Previous View | T27: none
A28: 25 | B28: civil-nx/gen-nx | C28: View | D28: View | E28: View Point | F28: Iso | T28: none
A29: 26 | B29: civil-nx/gen-nx | C29: View | D29: View | E29: View Point | F29: Left (-X) | T29: none
A30: 27 | B30: civil-nx/gen-nx | C30: View | D30: View | E30: View Point | F30: Right (+X) | T30: none
A31: 28 | B31: civil-nx/gen-nx | C31: View | D31: View | E31: View Point | F31: Front (-Y) | T31: none
A32: 29 | B32: civil-nx/gen-nx | C32: View | D32: View | E32: View Point | F32: Rear (+Y) | T32: none
A33: 30 | B33: civil-nx/gen-nx | C33: Node/Element | D33: Mesh | E33: Mesh | F33: Auto-mesh | T33: none
A34: 31 | B34: gen-nx | C34: Misc. | D34: Etc | E34: Imperfection | F34: Imperfection Data | T34: none
A35: 32 | B35: civil-nx/gen-nx | C35: View | D35: View | E35: View | F35: Redraw | H35: view | T35: none | Z35: =IF(OR(K34="",K34="TABLE"),"", _xlfn.TEXTJOIN(", ",TRUE, IF(E34<>"",E34&K34,""), IF(F34<>"",F34&K34,""), IF(G34<>"",G34&K34,"") )) | AA35: =IF(K34="","",IF(K34="TABLE","",K34)) | AB35: =IF(ISNUMBER(SEARCH("기존변경필요",SUBSTITUTE(TRIM(V34),CHAR(10)," "))),"", IFERROR( _xlfn.XLOOKUP(AA34,'기존 end point'!B:B,'기존 end point'!B:B,,0), ""))
A36: 33 | B36: civil-nx/gen-nx | C36: View | D36: View | E36: View Point | F36: Top (+Z) | H36: view | T36: none | Z36: =IF(OR(K35="",K35="TABLE"),"", _xlfn.TEXTJOIN(", ",TRUE, IF(E35<>"",E35&K35,""), IF(F35<>"",F35&K35,""), IF(G35<>"",G35&K35,"") )) | AA36: =IF(K35="","",IF(K35="TABLE","",K35)) | AB36: =IF(ISNUMBER(SEARCH("기존변경필요",SUBSTITUTE(TRIM(V35),CHAR(10)," "))),"", IFERROR( _xlfn.XLOOKUP(AA35,'기존 end point'!B:B,'기존 end point'!B:B,,0), ""))
A37: 34 | B37: civil-nx/gen-nx | C37: View | D37: View | E37: View Point | F37: Bottom (-Z) | H37: view | T37: none | Z37: =IF(OR(K36="",K36="TABLE"),"", _xlfn.TEXTJOIN(", ",TRUE, IF(E36<>"",E36&K36,""), IF(F36<>"",F36&K36,""), IF(G36<>"",G36&K36,"") )) | AA37: =IF(K36="","",IF(K36="TABLE","",K36)) | AB37: =IF(ISNUMBER(SEARCH("기존변경필요",SUBSTITUTE(TRIM(V36),CHAR(10)," "))),"", IFERROR( _xlfn.XLOOKUP(AA36,'기존 end point'!B:B,'기존 end point'!B:B,,0), ""))
A38: 35 | B38: civil-nx/gen-nx | C38: View | D38: View | E38: View Point | F38: Rotate Down | H38: view | T38: none | Z38: =IF(OR(K37="",K37="TABLE"),"", _xlfn.TEXTJOIN(", ",TRUE, IF(E37<>"",E37&K37,""), IF(F37<>"",F37&K37,""), IF(G37<>"",G37&K37,"") )) | AA38: =IF(K37="","",IF(K37="TABLE","",K37)) | AB38: =IF(ISNUMBER(SEARCH("기존변경필요",SUBSTITUTE(TRIM(V37),CHAR(10)," "))),"", IFERROR( _xlfn.XLOOKUP(AA37,'기존 end point'!B:B,'기존 end point'!B:B,,0), ""))
A39: 36 | B39: civil-nx/gen-nx | C39: View | D39: View | E39: Pan | F39: Pan | H39: view | T39: none | Z39: =IF(OR(K38="",K38="TABLE"),"", _xlfn.TEXTJOIN(", ",TRUE, IF(E38<>"",E38&K38,""), IF(F38<>"",F38&K38,""), IF(G38<>"",G38&K38,"") )) | AA39: =IF(K38="","",IF(K38="TABLE","",K38)) | AB39: =IF(ISNUMBER(SEARCH("기존변경필요",SUBSTITUTE(TRIM(V38),CHAR(10)," "))),"", IFERROR( _xlfn.XLOOKUP(AA38,'기존 end point'!B:B,'기존 end point'!B:B,,0), ""))
A40: 37 | B40: civil-nx/gen-nx | C40: View | D40: View | E40: Pan | F40: Left | H40: view | T40: none | Z40: =IF(OR(K39="",K39="TABLE"),"", _xlfn.TEXTJOIN(", ",TRUE, IF(E39<>"",E39&K39,""), IF(F39<>"",F39&K39,""), IF(G39<>"",G39&K39,"") )) | AA40: =IF(K39="","",IF(K39="TABLE","",K39)) | AB40: =IF(ISNUMBER(SEARCH("기존변경필요",SUBSTITUTE(TRIM(V39),CHAR(10)," "))),"", IFERROR( _xlfn.XLOOKUP(AA39,'기존 end point'!B:B,'기존 end point'!B:B,,0), ""))
...

Sheet Sheet1

Sheet PARAMETER 공통
B3: 항목 | C3: 등장 횟수 | D3: 엔드포인트 | E3: 비고
B4: Unbraced Length (L, Lb) | C4: 6 | D4: LENG | E4: 기존
B5: Effective Length Factor (K) | C5: 6 | D5: KFAC
B6: Equivalent Moment Correction Factor(Cm) | C6: 6 | D6: CMFT
B7: Moment Magnifier(B1/Delta_b, B2/Delta_s) | C7: 6 | D7: FMAG
B8: Modify Live Load Reduction Factor | C8: 6 | D8: MLLR
B9: Scale up Factor for Earthquake | C9: 6 | D9: SUEQ
B10: Modify Member Type | C10: 6 | D10: MBTP | E10: 기존
B11: Seismic Load Combination Type | C11: 6 | D11: EQCT
B14: 항목 | C14: 등장 횟수
B15: Definition of Frame | C15: 3 | D15: DCTL | E15: 기존
B16: Live Load Reduction Factor | C16: 3 | D16: LLRF
B17: Short/Long term Load Case | C17: 3 | D17: SLTC
B18: Load Contribution for Nonlinear Load Case | C18: 3 | D18: LCTB
B19: Member Assignment | C19: 3 | D19: MEMB | E19: 기존
B20: Reverse Member Load Direction | C20: 3 | D20: RMLD
B21: Undergroung Load Combination Type | C21: 3 | D21: ULCT
B22: Serviceability Load Combination Type | C22: 3 | D22: SLCT
B23: Limiting Slenderness Ratio | C23: 3 | D23: LTSR | E23: 기존
B25: 항목 | C25: 등장 횟수
B26: Haunched Beam Assignment | C26: 2 | D26: HCBM
B27: Strength Reduction Factors | C27: 2 | D27: SRDF
B28: Serviceability Parameters | C28: 2 (오타 포함) | D28: SERV
B29: Bending Coefficient(Cb) | C29: 2 | D29: CBFT
B30: Shear Coefficient(Cv) | C30: 2 | D30: SCOEF
B31: Specify Allowable Stresses | C31: 2 | D31: SPAS
B32: Seismic Load Resisting System by Member | C32: 2 | D32: SLRS
B33: Longitudinal Stiffener of Box Section | C33: 2 | D33: LSTIFB
B34: Combined Ratio Calculation Method for Circular Section | C34: 2 | D34: CRCMC
B35: Earthquake-Resistant Grade | C35: 2 | D35: EQRG
B36: Seismic Design Type | C36: 2 | D36: EQDT
B37: Moment Redistribution Factor | C37: 2 | D37: MRFAC
B38: Torsion Reduction Factor | C38: 2 | D38: TRFAC
B39: Uncertainty Load Combination Factor | C39: 2 | D39: ULCFAC
B40: Modify Member Strut Angle | C40: 2 | D40: MMSA
... B55: Boundary Element Method by Wall ID | C55: 2 | D55: BEMW

Sheet 입력 가이드
A1: 입력 가능한 값 참조 가이드
A3: 필드 | B3: 입력 가능한 값 | C3: 설명
A4: Plan | B4: (빈 값) | C4: 시작 안함
B5: progress | C5: 작업 중
B6: done | C6: 완료
B7: warning | C7: 경고/문제
A9: Dev | B9: (빈 값) | C9: 시작 안함
B10: progress | C10: 작업 중
B11: done | C11: 완료
B12: warning | C12: 경고/문제
A14: V&V | B14: (빈 값) | C14: 시작 안함
B15: progress | C15: 작업 중
B16: done | C16: 완료
B17: warning | C17: 경고/문제
A19: doc | B19: (빈 값) | C19: 시작 안함
B20: progress | C20: 작업 중
B21: done | C21: 완료
B22: warning | C22: 경고/문제
A24: Deploy | B24: (빈 값) | C24: 시작 안함
B25: progress | C25: 작업 중
B26: done | C26: 완료
B27: warning | C27: 경고/문제
A29: Issue | B29: (빈 값) | C29: 시작 안함
B30: progress | C30: 작업 중
B31: done | C31: 완료
B32: warning | C32: 경고/문제
A34: status | B34: progress | C34: 진행 중
B35: done | C35: 완료
B36: cancel | C36: 취소
B37: working | C37: 작업 중
B38: none | C38: 없음
A40: ※ 참고사항
A41: - 대소문자 구분 없이 입력 가능합니다 (예: Done, done, DONE 모두 동일)
A42: - status를 "done"으로 설정하면 모든 단계가 자동으로 "done"이 됩니다
A43: - 개별 단계를 수정하면 status는 자동으로 "progress"로 변경됩니다

Sheet 기존 end point
A1: endpoint
A2: /CONFIG/PROJECT | B2: =_xlfn.TEXTAFTER(A2,"/",-1)
A3: /CONFIG/VER | B3: =_xlfn.TEXTAFTER(A3,"/",-1)
A4: /DB/ACTL | B4: =_xlfn.TEXTAFTER(A4,"/",-1)
A5: /DB/ARPR | B5: =_xlfn.TEXTAFTER(A5,"/",-1)
A6: /DB/BCCT | B6: =_xlfn.TEXTAFTER(A6,"/",-1)
A7: /DB/BMLD | B7: =_xlfn.TEXTAFTER(A7,"/",-1)
A8: /DB/BNGR | B8: =_xlfn.TEXTAFTER(A8,"/",-1)
A9: /DB/BODF | B9: =_xlfn.TEXTAFTER(A9,"/",-1)
A10: /DB/BTMP | B10: =_xlfn.TEXTAFTER(A10,"/",-1)
A11: /DB/BUCK | B11: =_xlfn.TEXTAFTER(A11,"/",-1)
A12: /DB/CAMB | B12: =_xlfn.TEXTAFTER(A12,"/",-1)
A13: /DB/CCFC | B13: =_xlfn.TEXTAFTER(A13,"/",-1)
... A286: /VIEW/SELECT | B286: =_xlfn.TEXTAFTER(A286,"/",-1)
